<robot name="hand" xmlns:xacro="http://ros.org/wiki/xacro">
  <xacro:include filename="$(find sobit_edu_sim_description)/urdf/hand/hand.transmission.xacro" />
  <xacro:include filename="$(find sobit_edu_sim_description)/urdf/hand/hand.gazebo.xacro" />
  
  <xacro:macro name="hand" params="prefix_hand prefix_finger parent">

    <joint name="${prefix_hand}_base_joint" type="fixed">
      <parent link="${parent}" />
      <child link="${prefix_hand}_base_link" />
      <origin xyz="-0.02812 0.04061 0.05724" rpy="0.0 0.0 0.0" />
    </joint>

    <link name="${prefix_hand}_base_link">
      <visual>
        <origin xyz="0.02812 -0.04061 -0.05724" rpy="0.0 0.0 ${M_PI/2.0}" />
        <geometry>
          <mesh filename="package://sobit_edu_sim_description/meshes/hand/hand_back.stl" scale="0.001 0.001 0.001" />
        </geometry>
        <material name="black" />
      </visual>
      <collision>
        <origin xyz="0.02812 -0.04061 -0.05724" rpy="0.0 0.0 ${M_PI/2.0}" />
        <geometry>
          <mesh filename="package://sobit_edu_sim_description/meshes/hand/hand_back.stl" scale="0.001 0.001 0.001" />
        </geometry>
      </collision>
      <inertial>
        <origin xyz="0.0 0.0 0.0" rpy="0.0 0.0 0.0" />
        <mass value="0.01" />
        <inertia ixx="0.001" ixy="0.0" ixz="0.0"
                 iyy="0.001" iyz="0.0"
                 izz="0.001" />
      </inertial>
    </link>

    <joint name="${prefix_hand}_joint" type="revolute">
      <parent link="${prefix_hand}_base_link" />
      <child link="${prefix_hand}_inner_r_link" />
      <origin xyz="0 -0.05666 0.02054" rpy="0.0 0.0 0.0" />
      <axis xyz="-1 0 0" />
      <limit lower="${-M_PI/2.0}" upper="0" effort="1" velocity="1" />
    </joint>

    <link name="${prefix_hand}_inner_r_link">
      <visual>
        <origin xyz="0.0 0.0 0.0" rpy="${M_PI/2.0} 0.0 ${M_PI/2.0}" />
        <geometry>
          <mesh filename="package://sobit_edu_sim_description/meshes/hand/hand_inner_r.stl" scale="0.001 0.001 0.001" />
        </geometry>
        <material name="black" />
      </visual>
      <collision>
        <origin xyz="0.0 0.0 0.0" rpy="${M_PI/2.0} 0.0 ${M_PI/2.0}" />
        <geometry>
          <mesh filename="package://sobit_edu_sim_description/meshes/hand/hand_inner_r.stl" scale="0.001 0.001 0.001" />
        </geometry>
      </collision>
      <inertial>
        <origin xyz="0.0 0.0 0.0" rpy="0.0 0.0 0.0" />
        <mass value="0.01" />
        <inertia ixx="0.001" ixy="0.0" ixz="0.0"
                 iyy="0.001" iyz="0.0"
                 izz="0.001" />
      </inertial>
    </link>

    <joint name="${prefix_hand}_inner_l_joint" type="continuous">
      <parent link="${prefix_hand}_base_link" />
      <child link="${prefix_hand}_inner_l_link" />
      <origin xyz="0 -0.02456 0.02054" rpy="0.0 0.0 0.0" />
      <axis xyz="1 0 0" />
      <mimic joint="${prefix_hand}_joint" multiplier="1.0" offset="0" />
    </joint>
    <link name="${prefix_hand}_inner_l_link">
      <visual>
        <origin xyz="0.0 0.0 0.0" rpy="${M_PI/2.0} 0.0 ${M_PI/2.0}" />
        <geometry>
          <mesh filename="package://sobit_edu_sim_description/meshes/hand/hand_inner_l.stl" scale="0.001 0.001 0.001" />
        </geometry>
        <material name="black" />
      </visual>
      <collision>
        <origin xyz="0.0 0.0 0.0" rpy="${M_PI/2.0} 0.0 ${M_PI/2.0}" />
        <geometry>
          <mesh filename="package://sobit_edu_sim_description/meshes/hand/hand_inner_l.stl" scale="0.001 0.001 0.001" />
        </geometry>
      </collision>
      <inertial>
        <origin xyz="0.0 0.0 0.0" rpy="0.0 0.0 0.0" />
        <mass value="0.01" />
        <inertia ixx="0.001" ixy="0.0" ixz="0.0"
                 iyy="0.001" iyz="0.0"
                 izz="0.001" />
      </inertial>
    </link>

    <joint name="${prefix_hand}_${prefix_finger}_l_joint" type="continuous">
      <parent link="${prefix_hand}_inner_l_link" />
      <child link="${prefix_hand}_${prefix_finger}_l_link" />
      <origin xyz="0.019 0 0.08" rpy="0.0 0.0 0.0" />
      <axis xyz="1 0 0" />
      <mimic joint="${prefix_hand}_joint" multiplier="-1.0" offset="0" />
    </joint>

    <link name="${prefix_hand}_${prefix_finger}_l_link">
      <visual>
        <origin xyz="0.0 0.025 -0.03" rpy="${M_PI/2.0} 0.0 ${M_PI/2.0}" />
        <geometry>
          <mesh filename="package://sobit_edu_sim_description/meshes/hand/hand_finger_l.stl" scale="0.001 0.001 0.001" />
        </geometry>
        <material name="black" />
      </visual>
      <collision>
        <origin xyz="0.0 0.025 -0.03" rpy="${M_PI/2.0} 0.0 ${M_PI/2.0}" />
        <geometry>
          <mesh filename="package://sobit_edu_sim_description/meshes/hand/hand_finger_l.stl" scale="0.001 0.001 0.001" />
        </geometry>
      </collision>
      <inertial>
        <origin xyz="0.0 0.025 -0.03" rpy="0.0 0.0 0.0" />
        <mass value="0.01" />
        <inertia ixx="0.001" ixy="0.0" ixz="0.0"
                 iyy="0.001" iyz="0.0"
                 izz="0.001" />
      </inertial>
    </link>

    <joint name="${prefix_hand}_${prefix_finger}_r_joint" type="continuous">
      <parent link="${prefix_hand}_inner_r_link" />
      <child link="${prefix_hand}_${prefix_finger}_r_link" />
      <origin xyz="0.019 0 0.08" rpy="0.0 0.0 0.0" />
      <axis xyz="-1 0 0" />
      <mimic joint="${prefix_hand}_joint" multiplier="-1.0" offset="0" />
    </joint>

    <link name="${prefix_hand}_${prefix_finger}_r_link">
      <visual>
        <origin xyz="0.0 -0.025 -0.03" rpy="${M_PI/2.0} 0.0 ${M_PI/2.0}" />
        <geometry>
          <mesh filename="package://sobit_edu_sim_description/meshes/hand/hand_finger_r.stl" scale="0.001 0.001 0.001" />
        </geometry>
        <material name="black" />
      </visual>
      <collision>
        <origin xyz="0.0 -0.025 -0.03" rpy="${M_PI/2.0} 0.0 ${M_PI/2.0}" />
        <geometry>
          <mesh filename="package://sobit_edu_sim_description/meshes/hand/hand_finger_r.stl" scale="0.001 0.001 0.001" />
        </geometry>
      </collision>
      <inertial>
        <origin xyz="0.0 -0.025 -0.03" rpy="0.0 0.0 0.0" />
        <mass value="0.01" />
        <inertia ixx="0.001" ixy="0.0" ixz="0.0"
                 iyy="0.001" iyz="0.0"
                 izz="0.001" />
      </inertial>
    </link>

    <joint name="${prefix_hand}_outer_l_joint" type="continuous">
      <parent link="${prefix_hand}_${prefix_finger}_l_link" />
      <child link="${prefix_hand}_outer_l_link" />
      <origin xyz="-0.015 0.025 -0.03" rpy="0.0 0.0 0.0" />
      <axis xyz="1 0 0" />
      <mimic joint="${prefix_hand}_inner_l_joint" multiplier="1.0" offset="0" />
    </joint>

    <link name="${prefix_hand}_outer_l_link">
      <visual>
        <origin xyz="-0.004 0.0 -0.07" rpy="${M_PI/2.0} 0.0 ${M_PI/2.0}" />
        <geometry>
          <mesh filename="package://sobit_edu_sim_description/meshes/hand/hand_outer_l.stl" scale="0.001 0.001 0.001" />
        </geometry>
        <material name="black" />
      </visual>
      <collision>
        <origin xyz="-0.004 0.0 -0.07" rpy="${M_PI/2.0} 0.0 ${M_PI/2.0}" />
        <geometry>
          <mesh filename="package://sobit_edu_sim_description/meshes/hand/hand_outer_l.stl" scale="0.001 0.001 0.001" />
        </geometry>
      </collision>
      <inertial>
        <origin xyz="-0.004 0.0 -0.07" rpy="0.0 0.0 0.0" />
        <mass value="0.01" />
        <inertia ixx="0.001" ixy="0.0" ixz="0.0"
                 iyy="0.001" iyz="0.0"
                 izz="0.001" />
      </inertial>
    </link>

    <joint name="${prefix_hand}_outer_r_joint" type="continuous">
      <parent link="${prefix_hand}_${prefix_finger}_r_link" />
      <child link="${prefix_hand}_outer_r_link" />
      <origin xyz="-0.015 -0.025 -0.03" rpy="0.0 0.0 0.0" />
      <axis xyz="-1 0 0" />
      <mimic joint="${prefix_hand}_joint" multiplier="1.0" offset="0" />
    </joint>

    <link name="${prefix_hand}_outer_r_link">
      <visual>
        <origin xyz="-0.004 0.0 -0.07" rpy="${M_PI/2.0} 0.0 ${M_PI/2.0}" />
        <geometry>
          <mesh filename="package://sobit_edu_sim_description/meshes/hand/hand_outer_r.stl" scale="0.001 0.001 0.001" />
        </geometry>
        <material name="black" />
      </visual>
      <collision>
        <origin xyz="-0.004 0.0 -0.07" rpy="${M_PI/2.0} 0.0 ${M_PI/2.0}" />
        <geometry>
          <mesh filename="package://sobit_edu_sim_description/meshes/hand/hand_outer_r.stl" scale="0.001 0.001 0.001" />
        </geometry>
      </collision>
      <inertial>
        <origin xyz="0.0 0.0 0.0" rpy="0.0 0.0 0.0" />
        <mass value="0.01" />
        <inertia ixx="0.001" ixy="0.0" ixz="0.0"
                 iyy="0.001" iyz="0.0"
                 izz="0.001" />
      </inertial>
    </link>

    <xacro:hand_transmission prefix_hand="${prefix_hand}" prefix_finger="${prefix_finger}" />
    <xacro:hand_gazebo prefix="${prefix_hand}" />

  </xacro:macro>
</robot>