<?xml version="1.0" ?>
<!-- =================================================================================== -->
<!-- |    This document was autogenerated by xacro from sobit_edu.urdf.xacro           | -->
<!-- |    EDITING THIS FILE BY HAND IS NOT RECOMMENDED                                 | -->
<!-- =================================================================================== -->
<robot name="sobit_edu" xmlns:controller="http://playerstage.sourceforge.net/gazebo/xmlschema/#controller" xmlns:interface="http://playerstage.sourceforge.net/gazebo/xmlschema/#interface" xmlns:sensor="http://playerstage.sourceforge.net/gazebo/xmlschema/#sensor">
  <material name="wheel">
    <color rgba="0.2 0.2 0.2 1.0"/>
  </material>
  <material name="black">
    <color rgba="0.1 0.1 0.1 1.0"/>
  </material>
  <material name="red">
    <color rgba="1.0 0.0 0.0 1.0"/>
  </material>
  <material name="green">
    <color rgba="0.0 1.0 0.0 1.0"/>
  </material>
  <material name="blue">
    <color rgba="0.0 0.0 1.0 1.0"/>
  </material>
  <material name="white">
    <color rgba="1.0 1.0 1.0 1.0"/>
  </material>
  <material name="grey">
    <color rgba="0.3 0.3 0.3 1.0"/>
  </material>
  <material name="dark_grey">
    <color rgba="0.175 0.175 0.175 1.0"/>
  </material>
  <!-- <gazebo>
  <plugin name="object_controller" filename="libgazebo_ros_planar_move.so">
    <commandTopic>/mobile_base/commands/velocity</commandTopic>
    <odometryTopic>odom</odometryTopic>
    <odometryFrame>odom</odometryFrame>
    <odometryRate>20.0</odometryRate>
    <robotBaseFrame>base_footprint</robotBaseFrame>
    <cmdTimeout>2.0</cmdTimeout>
  </plugin>
</gazebo> -->
  <link name="base_footprint"/>
  <!--
       Base link is set at the bottom of the base mould.
       This is done to be compatible with the way base link
       was configured for turtlebot 1. Refer to
       https://github.com/turtlebot/turtlebot/issues/40
       To put the base link at the more oft used wheel
       axis, set the z-distance from the base_footprint
       to 0.352.
      -->
  <joint name="base_joint" type="fixed">
    <origin rpy="0 0 0" xyz="0 0 0.0102"/>
    <parent link="base_footprint"/>
    <child link="base_link"/>
  </joint>
  <link name="base_link">
    <visual>
      <geometry>
        <!-- new mesh -->
        <mesh filename="package://kobuki_description/meshes/main_body.dae"/>
      </geometry>
      <origin rpy="0 0 0" xyz="0.001 0 0.05199"/>
    </visual>
    <collision name="base">
      <geometry>
        <cylinder length="0.10938" radius="0.178"/>
      </geometry>
      <origin rpy="0 0 0" xyz="0.0 0 0.05949"/>
    </collision>
    <inertial>
      <!-- COM experimentally determined -->
      <origin xyz="0.01 0 0"/>
      <mass value="2.4"/>
      <!-- 2.4/2.6 kg for small/big battery pack -->
      <!-- Kobuki's inertia tensor is approximated by a cylinder with homogeneous mass distribution
             More details: http://en.wikipedia.org/wiki/List_of_moment_of_inertia_tensors
             m = 2.4 kg; h = 0.09 m; r = 0.175 m
             ixx = 1/12 * m * (3 * r^2 + h^2)
             iyy = 1/12 * m * (3 * r^2 + h^2)
             izz = 1/2 * m * r^2
          -->
      <inertia ixx="0.019995" ixy="0.0" ixz="0.0" iyy="0.019995" iyz="0.0" izz="0.03675"/>
    </inertial>
  </link>
  <joint name="wheel_l_joint" type="continuous">
    <parent link="base_link"/>
    <child link="wheel_l_link"/>
    <origin rpy="-1.5707963267948966 0 0" xyz="0.00 0.115 0.0250"/>
    <axis xyz="0 0 1"/>
  </joint>
  <link name="wheel_l_link">
    <visual>
      <geometry>
        <mesh filename="package://kobuki_description/meshes/wheel.dae"/>
      </geometry>
      <origin rpy="0 0 0" xyz="0 0 0"/>
    </visual>
    <collision>
      <geometry>
        <cylinder length="0.0206" radius="0.035"/>
      </geometry>
      <origin rpy="0 0 0" xyz="0 0 0"/>
    </collision>
    <inertial>
      <mass value="1"/>
      <origin xyz="0 0 0"/>
      <inertia ixx="0.001" ixy="0.0" ixz="0.0" iyy="0.001" iyz="0.0" izz="0.001"/>
    </inertial>
  </link>
  <joint name="wheel_r_joint" type="continuous">
    <parent link="base_link"/>
    <child link="wheel_r_link"/>
    <origin rpy="-1.5707963267948966 0 0" xyz="0.00 -0.115 0.0250"/>
    <axis xyz="0 0 1"/>
  </joint>
  <link name="wheel_r_link">
    <visual>
      <geometry>
        <mesh filename="package://kobuki_description/meshes/wheel.dae"/>
      </geometry>
      <origin rpy="0 0 0" xyz="0 0 0"/>
    </visual>
    <collision>
      <geometry>
        <cylinder length="0.0206" radius="0.035"/>
      </geometry>
      <origin rpy="0 0 0" xyz="0 0 0"/>
    </collision>
    <inertial>
      <mass value="1"/>
      <origin xyz="0 0 0"/>
      <inertia ixx="0.001" ixy="0.0" ixz="0.0" iyy="0.001" iyz="0.0" izz="0.001"/>
    </inertial>
  </link>
  <joint name="caster_f_joint" type="fixed">
    <parent link="base_link"/>
    <child link="caster_f_link"/>
    <origin rpy="-1.5707963267948966 0 0" xyz="0.115 0.0 0.007"/>
  </joint>
  <link name="caster_f_link">
    <collision>
      <geometry>
        <cylinder length="0.0176" radius="0.017"/>
      </geometry>
      <origin rpy="0 0 0" xyz="0 0 0"/>
    </collision>
    <inertial>
      <mass value="0.01"/>
      <origin xyz="0 0 0"/>
      <inertia ixx="0.001" ixy="0.0" ixz="0.0" iyy="0.001" iyz="0.0" izz="0.001"/>
    </inertial>
  </link>
  <joint name="caster_b_joint" type="fixed">
    <parent link="base_link"/>
    <child link="caster_b_link"/>
    <origin rpy="-1.5707963267948966 0 0" xyz="-0.135 0.0 0.009"/>
  </joint>
  <link name="caster_b_link">
    <collision>
      <geometry>
        <cylinder length="0.0176" radius="0.017"/>
      </geometry>
      <origin rpy="0 0 0" xyz="0 0 0"/>
    </collision>
    <inertial>
      <mass value="0.01"/>
      <origin xyz="0 0 0"/>
      <inertia ixx="0.001" ixy="0.0" ixz="0.0" iyy="0.001" iyz="0.0" izz="0.001"/>
    </inertial>
  </link>
  <!-- Kobuki's sensors -->
  <joint name="gyro_joint" type="fixed">
    <axis xyz="0 1 0"/>
    <origin rpy="0 0 0" xyz="0.056 0.062 0.0202"/>
    <parent link="base_link"/>
    <child link="gyro_link"/>
  </joint>
  <link name="gyro_link">
    <inertial>
      <mass value="0.001"/>
      <origin rpy="0 0 0" xyz="0 0 0"/>
      <inertia ixx="0.0001" ixy="0" ixz="0" iyy="0.000001" iyz="0" izz="0.0001"/>
    </inertial>
  </link>
  <joint name="cliff_sensor_l_joint" type="fixed">
    <origin rpy="0 1.5707963267948966 0" xyz="0.08734 0.13601 0.0214"/>
    <parent link="base_link"/>
    <child link="cliff_sensor_l_link"/>
  </joint>
  <link name="cliff_sensor_l_link">
    <inertial>
      <mass value="0.0001"/>
      <origin xyz="0 0 0"/>
      <inertia ixx="0.0001" ixy="0.0" ixz="0.0" iyy="0.0001" iyz="0.0" izz="0.0001"/>
    </inertial>
  </link>
  <joint name="cliff_sensor_r_joint" type="fixed">
    <origin rpy="0 1.5707963267948966 0" xyz="0.085 -0.13601 0.0214"/>
    <parent link="base_link"/>
    <child link="cliff_sensor_r_link"/>
  </joint>
  <link name="cliff_sensor_r_link">
    <inertial>
      <mass value="0.0001"/>
      <origin xyz="0 0 0"/>
      <inertia ixx="0.0001" ixy="0.0" ixz="0.0" iyy="0.0001" iyz="0.0" izz="0.0001"/>
    </inertial>
  </link>
  <joint name="cliff_sensor_f_joint" type="fixed">
    <origin rpy="0 1.5707963267948966 0" xyz="0.156 0.00 0.0214"/>
    <parent link="base_link"/>
    <child link="cliff_sensor_f_link"/>
  </joint>
  <link name="cliff_sensor_f_link">
    <inertial>
      <mass value="0.0001"/>
      <origin xyz="0 0 0"/>
      <inertia ixx="0.0001" ixy="0.0" ixz="0.0" iyy="0.0001" iyz="0.0" izz="0.0001"/>
    </inertial>
  </link>
  <gazebo reference="wheel_l_link">
    <mu1>1.0</mu1>
    <mu2>1.0</mu2>
    <kp>1000000.0</kp>
    <kd>100.0</kd>
    <minDepth>0.001</minDepth>
    <maxVel>1.0</maxVel>
  </gazebo>
  <gazebo reference="wheel_r_link">
    <mu1>1.0</mu1>
    <mu2>1.0</mu2>
    <kp>1000000.0</kp>
    <kd>100.0</kd>
    <minDepth>0.001</minDepth>
    <maxVel>1.0</maxVel>
  </gazebo>
  <gazebo reference="caster_front_link">
    <mu1>0.0</mu1>
    <mu2>0.0</mu2>
    <kp>1000000.0</kp>
    <kd>100.0</kd>
    <minDepth>0.001</minDepth>
    <maxVel>1.0</maxVel>
  </gazebo>
  <gazebo reference="caster_back_link">
    <mu1>0.0</mu1>
    <mu2>0.0</mu2>
    <kp>1000000.0</kp>
    <kd>100.0</kd>
    <minDepth>0.001</minDepth>
    <maxVel>1.0</maxVel>
  </gazebo>
  <gazebo reference="base_link">
    <mu1>0.3</mu1>
    <mu2>0.3</mu2>
    <sensor name="bumpers" type="contact">
      <always_on>1</always_on>
      <update_rate>50.0</update_rate>
      <visualize>true</visualize>
      <contact>
        <collision>base_footprint_fixed_joint_lump__base_collision</collision>
      </contact>
    </sensor>
  </gazebo>
  <gazebo reference="cliff_sensor_left_link">
    <sensor name="cliff_sensor_left" type="ray">
      <always_on>true</always_on>
      <update_rate>50</update_rate>
      <visualize>true</visualize>
      <ray>
        <scan>
          <horizontal>
            <samples>50</samples>
            <resolution>1.0</resolution>
            <min_angle>-0.0436</min_angle>
            <!-- -2.5 degree -->
            <max_angle>0.0436</max_angle>
            <!-- 2.5 degree -->
          </horizontal>
          <!--            Can't use vertical rays until this bug is resolved: -->
          <!--            https://bitbucket.org/osrf/gazebo/issue/509/vertical-sensor-doesnt-works -->
          <!--               <vertical> -->
          <!--                 <samples>50</samples> -->
          <!--                 <resolution>1.0</resolution> -->
          <!--                 <min_angle>-0.0436</min_angle>  -2.5 degree -->
          <!--                 <max_angle>0.0436</max_angle> 2.5 degree -->
          <!--               </vertical> -->
        </scan>
        <range>
          <min>0.01</min>
          <max>0.15</max>
          <resolution>1.0</resolution>
        </range>
      </ray>
    </sensor>
  </gazebo>
  <gazebo reference="cliff_sensor_right_link">
    <sensor name="cliff_sensor_right" type="ray">
      <always_on>true</always_on>
      <update_rate>50</update_rate>
      <visualize>true</visualize>
      <ray>
        <scan>
          <horizontal>
            <samples>50</samples>
            <resolution>1.0</resolution>
            <min_angle>-0.0436</min_angle>
            <!-- -2.5 degree -->
            <max_angle>0.0436</max_angle>
            <!-- 2.5 degree -->
          </horizontal>
          <!--            Can't use vertical rays until this bug is resolved: -->
          <!--            https://bitbucket.org/osrf/gazebo/issue/509/vertical-sensor-doesnt-works -->
          <!--               <vertical> -->
          <!--                 <samples>50</samples> -->
          <!--                 <resolution>1.0</resolution> -->
          <!--                 <min_angle>-0.0436</min_angle>  -2.5 degree -->
          <!--                 <max_angle>0.0436</max_angle> 2.5 degree -->
          <!--               </vertical> -->
        </scan>
        <range>
          <min>0.01</min>
          <max>0.15</max>
          <resolution>1.0</resolution>
        </range>
      </ray>
    </sensor>
  </gazebo>
  <gazebo reference="cliff_sensor_front_link">
    <sensor name="cliff_sensor_front" type="ray">
      <always_on>true</always_on>
      <update_rate>50</update_rate>
      <visualize>true</visualize>
      <ray>
        <scan>
          <horizontal>
            <samples>50</samples>
            <resolution>1.0</resolution>
            <min_angle>-0.0436</min_angle>
            <!-- -2.5 degree -->
            <max_angle>0.0436</max_angle>
            <!-- 2.5 degree -->
          </horizontal>
          <!--               Can't use vertical rays until this bug is resolved: -->
          <!--            https://bitbucket.org/osrf/gazebo/issue/509/vertical-sensor-doesnt-works -->
          <!--               <vertical> -->
          <!--                 <samples>50</samples> -->
          <!--                 <resolution>1.0</resolution> -->
          <!--                 <min_angle>-0.0436</min_angle>  -2.5 degree -->
          <!--                 <max_angle>0.0436</max_angle> 2.5 degree -->
          <!--               </vertical> -->
        </scan>
        <range>
          <min>0.01</min>
          <max>0.15</max>
          <resolution>1.0</resolution>
        </range>
      </ray>
    </sensor>
  </gazebo>
  <gazebo reference="gyro_link">
    <sensor name="imu" type="imu">
      <always_on>true</always_on>
      <update_rate>50</update_rate>
      <visualize>false</visualize>
      <imu>
        <noise>
          <type>gaussian</type>
          <rate>
            <mean>0.0</mean>
            <stddev>1.96e-06</stddev>
            <!-- 0.25 x 0.25 (deg/s) -->
            <bias_mean>0.0</bias_mean>
            <bias_stddev>0.0</bias_stddev>
          </rate>
          <accel>
            <!-- not used in the plugin and real robot, hence using tutorial values -->
            <mean>0.0</mean>
            <stddev>1.7e-2</stddev>
            <bias_mean>0.1</bias_mean>
            <bias_stddev>0.001</bias_stddev>
          </accel>
        </noise>
      </imu>
    </sensor>
  </gazebo>
  <gazebo>
    <plugin filename="libgazebo_ros_kobuki.so" name="kobuki_controller">
      <publish_tf>1</publish_tf>
      <left_wheel_joint_name>wheel_l_joint</left_wheel_joint_name>
      <right_wheel_joint_name>wheel_r_joint</right_wheel_joint_name>
      <wheel_separation>.230</wheel_separation>
      <wheel_diameter>0.070</wheel_diameter>
      <torque>1.0</torque>
      <velocity_command_timeout>0.6</velocity_command_timeout>
      <cliff_sensor_left_name>cliff_sensor_left</cliff_sensor_left_name>
      <cliff_sensor_center_name>cliff_sensor_front</cliff_sensor_center_name>
      <cliff_sensor_right_name>cliff_sensor_right</cliff_sensor_right_name>
      <cliff_detection_threshold>0.04</cliff_detection_threshold>
      <bumper_name>bumpers</bumper_name>
      <imu_name>imu</imu_name>
    </plugin>
  </gazebo>
  <gazebo reference="base_link">
    <selfCollide>false</selfCollide>
    <mu1>1.0</mu1>
    <mu2>1.0</mu2>
  </gazebo>
  <gazebo reference="wheel_l_link">
    <selfCollide>false</selfCollide>
    <mu1>1.0</mu1>
    <mu2>1.0</mu2>
  </gazebo>
  <gazebo reference="wheel_r_link">
    <selfCollide>false</selfCollide>
    <mu1>1.0</mu1>
    <mu2>1.0</mu2>
  </gazebo>
  <gazebo>
    <plugin filename="libgazebo_ros_diff_drive.so" name="differential_drive_controller">
      <leftJoint>wheel_l_joint</leftJoint>
      <rightJoint>wheel_r_joint</rightJoint>
      <wheelSeparation>0.23</wheelSeparation>
      <wheelDiameter>0.070</wheelDiameter>
      <wheelAcceleration>1.0</wheelAcceleration>
      <wheelTorque>20</wheelTorque>
      <commandTopic>/mobile_base/commands/velocity</commandTopic>
      <odometryTopic>odom</odometryTopic>
      <odometryFrame>odom</odometryFrame>
      <robotBaseFrame>base_footprint</robotBaseFrame>
      <odometrySource>1</odometrySource>
      <publishWheelTF>true</publishWheelTF>
      <publishOdom>true</publishOdom>
      <publishWheelJointState>true</publishWheelJointState>
      <legacyMode>false</legacyMode>
      <updateRate>50.0</updateRate>
    </plugin>
  </gazebo>
  <joint name="pole_bottom_0_joint" type="fixed">
    <origin rpy="0.0 0.0 0.0" xyz="0.12 0.082 0.08835"/>
    <parent link="base_link"/>
    <child link="pole_bottom_0_link"/>
  </joint>
  <link name="pole_bottom_0_link">
    <visual>
      <origin rpy="1.5707963267948966 0.0 0.0" xyz="0.0 0.0 0.0"/>
      <geometry>
        <!-- <mesh filename="package://turtlebot_description/meshes/stacks/hexagons/pole_bottom.dae" /> -->
        <mesh filename="package://sobit_edu_sim_description/meshes/body/pole_bottom_39mm.stl" scale="0.001 0.001 0.001"/>
      </geometry>
      <material name="grey"/>
    </visual>
    <collision>
      <origin rpy="0.0 0.0 0.0" xyz="0.0 0.0 0.0"/>
      <geometry>
        <cylinder length="0.0492" radius="0.006"/>
      </geometry>
    </collision>
    <inertial>
      <mass value="0.008"/>
      <origin rpy="0.0 0.0 0.0" xyz="0.0 0.0 0.0"/>
      <inertia ixx="0.000001686" ixy="0.0" ixz="0.0" iyy="0.000001686" iyz="0.0" izz="0.000000144"/>
    </inertial>
  </link>
  <joint name="pole_bottom_1_joint" type="fixed">
    <origin rpy="0.0 0.0 0.0" xyz="0.055 0.12 0.08835"/>
    <parent link="base_link"/>
    <child link="pole_bottom_1_link"/>
  </joint>
  <link name="pole_bottom_1_link">
    <visual>
      <origin rpy="1.5707963267948966 0.0 0.0" xyz="0.0 0.0 0.0"/>
      <geometry>
        <!-- <mesh filename="package://turtlebot_description/meshes/stacks/hexagons/pole_bottom.dae" /> -->
        <mesh filename="package://sobit_edu_sim_description/meshes/body/pole_bottom_39mm.stl" scale="0.001 0.001 0.001"/>
      </geometry>
      <material name="grey"/>
    </visual>
    <collision>
      <origin rpy="0.0 0.0 0.0" xyz="0.0 0.0 0.0"/>
      <geometry>
        <cylinder length="0.0492" radius="0.006"/>
      </geometry>
    </collision>
    <inertial>
      <mass value="0.008"/>
      <origin rpy="0.0 0.0 0.0" xyz="0.0 0.0 0.0"/>
      <inertia ixx="0.000001686" ixy="0.0" ixz="0.0" iyy="0.000001686" iyz="0.0" izz="0.000000144"/>
    </inertial>
  </link>
  <joint name="pole_bottom_2_joint" type="fixed">
    <origin rpy="0.0 0.0 0.0" xyz="-0.055 0.12 0.08835"/>
    <parent link="base_link"/>
    <child link="pole_bottom_2_link"/>
  </joint>
  <link name="pole_bottom_2_link">
    <visual>
      <origin rpy="1.5707963267948966 0.0 0.0" xyz="0.0 0.0 0.0"/>
      <geometry>
        <!-- <mesh filename="package://turtlebot_description/meshes/stacks/hexagons/pole_bottom.dae" /> -->
        <mesh filename="package://sobit_edu_sim_description/meshes/body/pole_bottom_39mm.stl" scale="0.001 0.001 0.001"/>
      </geometry>
      <material name="grey"/>
    </visual>
    <collision>
      <origin rpy="0.0 0.0 0.0" xyz="0.0 0.0 0.0"/>
      <geometry>
        <cylinder length="0.0492" radius="0.006"/>
      </geometry>
    </collision>
    <inertial>
      <mass value="0.008"/>
      <origin rpy="0.0 0.0 0.0" xyz="0.0 0.0 0.0"/>
      <inertia ixx="0.000001686" ixy="0.0" ixz="0.0" iyy="0.000001686" iyz="0.0" izz="0.000000144"/>
    </inertial>
  </link>
  <joint name="pole_bottom_3_joint" type="fixed">
    <origin rpy="0.0 0.0 0.0" xyz="0.12 -0.082 0.08835"/>
    <parent link="base_link"/>
    <child link="pole_bottom_3_link"/>
  </joint>
  <link name="pole_bottom_3_link">
    <visual>
      <origin rpy="1.5707963267948966 0.0 0.0" xyz="0.0 0.0 0.0"/>
      <geometry>
        <!-- <mesh filename="package://turtlebot_description/meshes/stacks/hexagons/pole_bottom.dae" /> -->
        <mesh filename="package://sobit_edu_sim_description/meshes/body/pole_bottom_39mm.stl" scale="0.001 0.001 0.001"/>
      </geometry>
      <material name="grey"/>
    </visual>
    <collision>
      <origin rpy="0.0 0.0 0.0" xyz="0.0 0.0 0.0"/>
      <geometry>
        <cylinder length="0.0492" radius="0.006"/>
      </geometry>
    </collision>
    <inertial>
      <mass value="0.008"/>
      <origin rpy="0.0 0.0 0.0" xyz="0.0 0.0 0.0"/>
      <inertia ixx="0.000001686" ixy="0.0" ixz="0.0" iyy="0.000001686" iyz="0.0" izz="0.000000144"/>
    </inertial>
  </link>
  <joint name="pole_bottom_4_joint" type="fixed">
    <origin rpy="0.0 0.0 0.0" xyz="0.055 -0.12 0.08835"/>
    <parent link="base_link"/>
    <child link="pole_bottom_4_link"/>
  </joint>
  <link name="pole_bottom_4_link">
    <visual>
      <origin rpy="1.5707963267948966 0.0 0.0" xyz="0.0 0.0 0.0"/>
      <geometry>
        <!-- <mesh filename="package://turtlebot_description/meshes/stacks/hexagons/pole_bottom.dae" /> -->
        <mesh filename="package://sobit_edu_sim_description/meshes/body/pole_bottom_39mm.stl" scale="0.001 0.001 0.001"/>
      </geometry>
      <material name="grey"/>
    </visual>
    <collision>
      <origin rpy="0.0 0.0 0.0" xyz="0.0 0.0 0.0"/>
      <geometry>
        <cylinder length="0.0492" radius="0.006"/>
      </geometry>
    </collision>
    <inertial>
      <mass value="0.008"/>
      <origin rpy="0.0 0.0 0.0" xyz="0.0 0.0 0.0"/>
      <inertia ixx="0.000001686" ixy="0.0" ixz="0.0" iyy="0.000001686" iyz="0.0" izz="0.000000144"/>
    </inertial>
  </link>
  <joint name="pole_bottom_5_joint" type="fixed">
    <origin rpy="0.0 0.0 0.0" xyz="-0.055 -0.12 0.08835"/>
    <parent link="base_link"/>
    <child link="pole_bottom_5_link"/>
  </joint>
  <link name="pole_bottom_5_link">
    <visual>
      <origin rpy="1.5707963267948966 0.0 0.0" xyz="0.0 0.0 0.0"/>
      <geometry>
        <!-- <mesh filename="package://turtlebot_description/meshes/stacks/hexagons/pole_bottom.dae" /> -->
        <mesh filename="package://sobit_edu_sim_description/meshes/body/pole_bottom_39mm.stl" scale="0.001 0.001 0.001"/>
      </geometry>
      <material name="grey"/>
    </visual>
    <collision>
      <origin rpy="0.0 0.0 0.0" xyz="0.0 0.0 0.0"/>
      <geometry>
        <cylinder length="0.0492" radius="0.006"/>
      </geometry>
    </collision>
    <inertial>
      <mass value="0.008"/>
      <origin rpy="0.0 0.0 0.0" xyz="0.0 0.0 0.0"/>
      <inertia ixx="0.000001686" ixy="0.0" ixz="0.0" iyy="0.000001686" iyz="0.0" izz="0.000000144"/>
    </inertial>
  </link>
  <joint name="plate_bottom_joint" type="fixed">
    <origin rpy="0.0 0.0 0.0" xyz="0.02364 0.0 0.1306"/>
    <parent link="base_link"/>
    <child link="plate_bottom_link"/>
  </joint>
  <link name="plate_bottom_link">
    <visual>
      <origin rpy="0.0 0.0 0.0" xyz="0.0 0.0 0.0"/>
      <geometry>
        <mesh filename="package://turtlebot_description/meshes/stacks/hexagons/plate_bottom.dae"/>
      </geometry>
    </visual>
    <collision>
      <origin rpy="0.0 0.0 0.0" xyz="-0.02364 0.0 0.0"/>
      <geometry>
        <cylinder length="0.006" radius="0.170"/>
      </geometry>
    </collision>
    <inertial>
      <mass value="0.520"/>
      <origin xyz="0.0 0.0 0.0"/>
      <inertia ixx="0.003328" ixy="0.0" ixz="0.0" iyy="0.003328" iyz="0.0" izz="0.006656"/>
    </inertial>
  </link>
  <!-- <xacro:stack_middle_pole parent="${parent}" number="0" x_loc= "0.0381" y_loc= "0.1505" z_loc="0.1640" />
    <xacro:stack_middle_pole parent="${parent}" number="1" x_loc= "0.0381" y_loc="-0.1505" z_loc="0.1640" />
    <xacro:stack_middle_pole parent="${parent}" number="2" x_loc="-0.0381" y_loc= "0.1505" z_loc="0.1640" />
    <xacro:stack_middle_pole parent="${parent}" number="3" x_loc="-0.0381" y_loc="-0.1505" z_loc="0.1640" /> -->
  <joint name="pole_middle_4_joint" type="fixed">
    <origin rpy="0.0 0.0 0.0" xyz="0.0381 0.1505 0.13385"/>
    <parent link="base_link"/>
    <child link="pole_middle_4_link"/>
  </joint>
  <link name="pole_middle_4_link">
    <visual>
      <origin rpy="1.5707963267948966 0.0 0.0" xyz="0.0 0.0 0.0"/>
      <geometry>
        <!-- <mesh filename="package://turtlebot_description/meshes/stacks/hexagons/pole_middle.dae" /> -->
        <mesh filename="package://sobit_edu_sim_description/meshes/body/pole_middle_90mm.stl" scale="0.001 0.001 0.001"/>
      </geometry>
      <material name="grey"/>
    </visual>
    <collision>
      <origin rpy="0.0 0.0 0.0" xyz="0.0 0.0 0.0"/>
      <geometry>
        <cylinder length="0.0608" radius="0.006"/>
      </geometry>
    </collision>
    <inertial>
      <mass value="0.012"/>
      <origin xyz="0.0 0.0 0.0"/>
      <inertia ixx="0.000003805" ixy="0.0" ixz="0.0" iyy="0.000003805" iyz="0.0" izz="0.000000216"/>
    </inertial>
  </link>
  <joint name="pole_middle_5_joint" type="fixed">
    <origin rpy="0.0 0.0 0.0" xyz="0.0381 -0.1505 0.13385"/>
    <parent link="base_link"/>
    <child link="pole_middle_5_link"/>
  </joint>
  <link name="pole_middle_5_link">
    <visual>
      <origin rpy="1.5707963267948966 0.0 0.0" xyz="0.0 0.0 0.0"/>
      <geometry>
        <!-- <mesh filename="package://turtlebot_description/meshes/stacks/hexagons/pole_middle.dae" /> -->
        <mesh filename="package://sobit_edu_sim_description/meshes/body/pole_middle_90mm.stl" scale="0.001 0.001 0.001"/>
      </geometry>
      <material name="grey"/>
    </visual>
    <collision>
      <origin rpy="0.0 0.0 0.0" xyz="0.0 0.0 0.0"/>
      <geometry>
        <cylinder length="0.0608" radius="0.006"/>
      </geometry>
    </collision>
    <inertial>
      <mass value="0.012"/>
      <origin xyz="0.0 0.0 0.0"/>
      <inertia ixx="0.000003805" ixy="0.0" ixz="0.0" iyy="0.000003805" iyz="0.0" izz="0.000000216"/>
    </inertial>
  </link>
  <joint name="pole_middle_6_joint" type="fixed">
    <origin rpy="0.0 0.0 0.0" xyz="-0.0381 0.1505 0.13385"/>
    <parent link="base_link"/>
    <child link="pole_middle_6_link"/>
  </joint>
  <link name="pole_middle_6_link">
    <visual>
      <origin rpy="1.5707963267948966 0.0 0.0" xyz="0.0 0.0 0.0"/>
      <geometry>
        <!-- <mesh filename="package://turtlebot_description/meshes/stacks/hexagons/pole_middle.dae" /> -->
        <mesh filename="package://sobit_edu_sim_description/meshes/body/pole_middle_90mm.stl" scale="0.001 0.001 0.001"/>
      </geometry>
      <material name="grey"/>
    </visual>
    <collision>
      <origin rpy="0.0 0.0 0.0" xyz="0.0 0.0 0.0"/>
      <geometry>
        <cylinder length="0.0608" radius="0.006"/>
      </geometry>
    </collision>
    <inertial>
      <mass value="0.012"/>
      <origin xyz="0.0 0.0 0.0"/>
      <inertia ixx="0.000003805" ixy="0.0" ixz="0.0" iyy="0.000003805" iyz="0.0" izz="0.000000216"/>
    </inertial>
  </link>
  <joint name="pole_middle_7_joint" type="fixed">
    <origin rpy="0.0 0.0 0.0" xyz="-0.0381 -0.1505 0.13385"/>
    <parent link="base_link"/>
    <child link="pole_middle_7_link"/>
  </joint>
  <link name="pole_middle_7_link">
    <visual>
      <origin rpy="1.5707963267948966 0.0 0.0" xyz="0.0 0.0 0.0"/>
      <geometry>
        <!-- <mesh filename="package://turtlebot_description/meshes/stacks/hexagons/pole_middle.dae" /> -->
        <mesh filename="package://sobit_edu_sim_description/meshes/body/pole_middle_90mm.stl" scale="0.001 0.001 0.001"/>
      </geometry>
      <material name="grey"/>
    </visual>
    <collision>
      <origin rpy="0.0 0.0 0.0" xyz="0.0 0.0 0.0"/>
      <geometry>
        <cylinder length="0.0608" radius="0.006"/>
      </geometry>
    </collision>
    <inertial>
      <mass value="0.012"/>
      <origin xyz="0.0 0.0 0.0"/>
      <inertia ixx="0.000003805" ixy="0.0" ixz="0.0" iyy="0.000003805" iyz="0.0" izz="0.000000216"/>
    </inertial>
  </link>
  <joint name="plate_middle_joint" type="fixed">
    <origin rpy="0.0 0.0 0.0" xyz="-0.01364 0.0 0.2271"/>
    <parent link="base_link"/>
    <child link="plate_middle_link"/>
  </joint>
  <link name="plate_middle_link">
    <visual>
      <origin rpy="0.0 0.0 0.0" xyz="0.0 0.0 0.0"/>
      <geometry>
        <mesh filename="package://turtlebot_description/meshes/stacks/hexagons/plate_middle.dae"/>
      </geometry>
    </visual>
    <collision>
      <origin rpy="0.0 0.0 0.0" xyz="0.01364 0.0 0.0"/>
      <geometry>
        <mesh filename="package://turtlebot_description/meshes/stacks/hexagons/plate_simple.stl" scale="0.001 0.001 0.001"/>
      </geometry>
    </collision>
    <inertial>
      <mass value="0.520"/>
      <origin xyz="0.0 0.0 0.0"/>
      <inertia ixx="0.003328" ixy="0.0" ixz="0.0" iyy="0.003328" iyz="0.0" izz="0.006656"/>
    </inertial>
  </link>
  <joint name="pole_top_0_joint" type="fixed">
    <origin rpy="0.0 0.0 0.0" xyz="0.0381 0.1505 0.23035"/>
    <parent link="base_link"/>
    <child link="pole_top_0_link"/>
  </joint>
  <link name="pole_top_0_link">
    <visual>
      <origin rpy="1.5707963267948966 0.0 0.0" xyz=" 0 0.0 0.0"/>
      <geometry>
        <!-- <mesh filename="package://turtlebot_description/meshes/stacks/hexagons/pole_top.dae" /> -->
        <mesh filename="package://sobit_edu_sim_description/meshes/body/pole_top_200mm.stl" scale="0.001 0.001 0.001"/>
      </geometry>
      <material name="grey"/>
    </visual>
    <collision>
      <origin rpy="0.0 0.0 0.0" xyz="0.0 0.0 0.0"/>
      <geometry>
        <cylinder length="0.2032" radius="0.006"/>
      </geometry>
    </collision>
    <inertial>
      <mass value="0.060"/>
      <origin xyz="0.0 0.0 0.0"/>
      <inertia ixx="0.000206991" ixy="0.0" ixz="0.0" iyy="0.000206991" iyz="0.0" izz="0.000001080"/>
    </inertial>
  </link>
  <joint name="pole_top_1_joint" type="fixed">
    <origin rpy="0.0 0.0 0.0" xyz="0.0381 -0.1505 0.23035"/>
    <parent link="base_link"/>
    <child link="pole_top_1_link"/>
  </joint>
  <link name="pole_top_1_link">
    <visual>
      <origin rpy="1.5707963267948966 0.0 0.0" xyz=" 0 0.0 0.0"/>
      <geometry>
        <!-- <mesh filename="package://turtlebot_description/meshes/stacks/hexagons/pole_top.dae" /> -->
        <mesh filename="package://sobit_edu_sim_description/meshes/body/pole_top_200mm.stl" scale="0.001 0.001 0.001"/>
      </geometry>
      <material name="grey"/>
    </visual>
    <collision>
      <origin rpy="0.0 0.0 0.0" xyz="0.0 0.0 0.0"/>
      <geometry>
        <cylinder length="0.2032" radius="0.006"/>
      </geometry>
    </collision>
    <inertial>
      <mass value="0.060"/>
      <origin xyz="0.0 0.0 0.0"/>
      <inertia ixx="0.000206991" ixy="0.0" ixz="0.0" iyy="0.000206991" iyz="0.0" izz="0.000001080"/>
    </inertial>
  </link>
  <joint name="pole_top_2_joint" type="fixed">
    <origin rpy="0.0 0.0 0.0" xyz="-0.0381 0.1505 0.23035"/>
    <parent link="base_link"/>
    <child link="pole_top_2_link"/>
  </joint>
  <link name="pole_top_2_link">
    <visual>
      <origin rpy="1.5707963267948966 0.0 0.0" xyz=" 0 0.0 0.0"/>
      <geometry>
        <!-- <mesh filename="package://turtlebot_description/meshes/stacks/hexagons/pole_top.dae" /> -->
        <mesh filename="package://sobit_edu_sim_description/meshes/body/pole_top_200mm.stl" scale="0.001 0.001 0.001"/>
      </geometry>
      <material name="grey"/>
    </visual>
    <collision>
      <origin rpy="0.0 0.0 0.0" xyz="0.0 0.0 0.0"/>
      <geometry>
        <cylinder length="0.2032" radius="0.006"/>
      </geometry>
    </collision>
    <inertial>
      <mass value="0.060"/>
      <origin xyz="0.0 0.0 0.0"/>
      <inertia ixx="0.000206991" ixy="0.0" ixz="0.0" iyy="0.000206991" iyz="0.0" izz="0.000001080"/>
    </inertial>
  </link>
  <joint name="pole_top_3_joint" type="fixed">
    <origin rpy="0.0 0.0 0.0" xyz="-0.0381 -0.1505 0.23035"/>
    <parent link="base_link"/>
    <child link="pole_top_3_link"/>
  </joint>
  <link name="pole_top_3_link">
    <visual>
      <origin rpy="1.5707963267948966 0.0 0.0" xyz=" 0 0.0 0.0"/>
      <geometry>
        <!-- <mesh filename="package://turtlebot_description/meshes/stacks/hexagons/pole_top.dae" /> -->
        <mesh filename="package://sobit_edu_sim_description/meshes/body/pole_top_200mm.stl" scale="0.001 0.001 0.001"/>
      </geometry>
      <material name="grey"/>
    </visual>
    <collision>
      <origin rpy="0.0 0.0 0.0" xyz="0.0 0.0 0.0"/>
      <geometry>
        <cylinder length="0.2032" radius="0.006"/>
      </geometry>
    </collision>
    <inertial>
      <mass value="0.060"/>
      <origin xyz="0.0 0.0 0.0"/>
      <inertia ixx="0.000206991" ixy="0.0" ixz="0.0" iyy="0.000206991" iyz="0.0" izz="0.000001080"/>
    </inertial>
  </link>
  <!-- <xacro:stack_3d_sensor_pole parent="${parent}" number="0" x_loc="-0.1024" y_loc= "0.098" z_loc="0.2372" /> -->
  <!-- <xacro:stack_3d_sensor_pole parent="${parent}" number="1" x_loc="-0.1024" y_loc="-0.098" z_loc="0.2372" /> -->
  <joint name="plate_top_joint" type="fixed">
    <origin rpy="0.0 0.0 0.0" xyz="-0.01364 0.0 0.4336"/>
    <parent link="base_link"/>
    <child link="plate_top_link"/>
  </joint>
  <link name="plate_top_link">
    <visual>
      <!-- <origin xyz="0.0 0.0 -0.00325" rpy="0.0 0.0 0.0" /> -->
      <origin rpy="0.0 0.0 0.0" xyz="0.0 0.0 -0.0"/>
      <geometry>
        <mesh filename="package://turtlebot_description/meshes/stacks/hexagons/plate_top.dae"/>
      </geometry>
    </visual>
    <collision>
      <origin rpy="0.0 0.0 0.0" xyz="0.01364 0.0 0.0"/>
      <geometry>
        <mesh filename="package://turtlebot_description/meshes/stacks/hexagons/plate_simple.stl" scale="0.001 0.001 0.001"/>
      </geometry>
    </collision>
    <inertial>
      <mass value="0.520"/>
      <origin xyz="0.0 0.0 0.0"/>
      <inertia ixx="0.003328" ixy="0.0" ixz="0.0" iyy="0.003328" iyz="0.0" izz="0.006656"/>
    </inertial>
  </link>
  <joint name="cover_joint" type="fixed">
    <origin rpy="0.0 0.0 0.0" xyz="0.186627 0.0 0.00325"/>
    <parent link="plate_top_link"/>
    <child link="cover_link"/>
  </joint>
  <link name="cover_link">
    <visual>
      <origin rpy="0.0 1.5707963267948966 -1.5707963267948966" xyz="0.0 0.0 0.0"/>
      <geometry>
        <mesh filename="package://sobit_edu_sim_description/meshes/body/cover.stl" scale="0.001 0.001 0.001"/>
      </geometry>
      <material name="blue"/>
    </visual>
    <collision>
      <origin rpy="0.0 1.5707963267948966 -1.5707963267948966" xyz="0.0 0.0 0.0"/>
      <geometry>
        <mesh filename="package://sobit_edu_sim_description/meshes/body/cover.stl" scale="0.001 0.001 0.001"/>
      </geometry>
    </collision>
    <inertial>
      <origin rpy="0.0 0.0 0.0" xyz="0.0 0.0 0.0"/>
      <mass value="1"/>
      <inertia ixx="0.0001" ixy="0.0" ixz="0.0" iyy="0.0001" iyz="0.0" izz="0.0001"/>
    </inertial>
  </link>
  <joint name="arm_base_joint" type="fixed">
    <parent link="plate_top_link"/>
    <child link="arm_base_link"/>
    <origin rpy="0.0 0.0 0.0" xyz="0.123481 0.0 0.00325"/>
    <!-- <origin xyz="0.0 0.0 0.0" rpy="0.0 0.0 0.0" /> -->
  </joint>
  <link name="arm_base_link">
    <visual>
      <origin rpy="0.0 0.0 1.5707963267948966" xyz="0.0 0.0 0.0"/>
      <geometry>
        <mesh filename="package://sobit_edu_sim_description/meshes/arm/Assembly_2.stl" scale="1.0 1.0 1.0"/>
      </geometry>
      <material name="black"/>
    </visual>
    <collision>
      <origin rpy="0.0 0.0 1.5707963267948966" xyz="0.0 0.0 0.0"/>
      <geometry>
        <mesh filename="package://sobit_edu_sim_description/meshes/arm/Assembly_2.stl" scale="1.0 1.0 1.0"/>
      </geometry>
    </collision>
    <inertial>
      <origin rpy="0.0 0.0 0.0" xyz="0.0 0.0 0.0"/>
      <mass value="0.00008"/>
      <inertia ixx="1.0" ixy="0.0" ixz="0.0" iyy="1.0" iyz="0.0" izz="1.0"/>
    </inertial>
  </link>
  <joint name="arm_shoulder_pan_joint" type="revolute">
    <parent link="arm_base_link"/>
    <child link="arm_shoulder_pan_link"/>
    <origin rpy="0.0 0.0 0.0" xyz="0.008769 0.0 0.043"/>
    <axis xyz="0 0 1"/>
    <limit effort="30" lower="-3.141592653589793" upper="3.141592653589793" velocity="1.5707963267948966"/>
  </joint>
  <link name="arm_shoulder_pan_link">
    <visual>
      <origin rpy="0.0 0.0 1.5707963267948966" xyz="0.0 0.0 0.0"/>
      <geometry>
        <mesh filename="package://sobit_edu_sim_description/meshes/arm/Assembly_3.stl" scale="1.0 1.0 1.0"/>
      </geometry>
      <material name="black"/>
    </visual>
    <collision>
      <origin rpy="0.0 0.0 1.5707963267948966" xyz="0.0 0.0 0.0"/>
      <geometry>
        <mesh filename="package://sobit_edu_sim_description/meshes/arm/Assembly_3.stl" scale="1.0 1.0 1.0"/>
      </geometry>
    </collision>
    <inertial>
      <origin rpy="0.0 0.0 0.0" xyz="0.0 0.0 0.0"/>
      <mass value="0.0008"/>
      <inertia ixx="1.0" ixy="0.0" ixz="0.0" iyy="1.0" iyz="0.0" izz="1.0"/>
    </inertial>
  </link>
  <joint name="arm_shoulder_1_tilt_joint" type="revolute">
    <parent link="arm_shoulder_pan_link"/>
    <child link="arm_shoulder_1_tilt_link"/>
    <origin rpy="0.0 1.5707963267948966 0.0" xyz="0.0 0.0 0.0405"/>
    <axis xyz="0 -1 0"/>
    <limit effort="30" lower="-1.5707963267948966" upper="1.5707963267948966" velocity="1.5707963267948966"/>
  </joint>
  <link name="arm_shoulder_1_tilt_link">
    <visual>
      <origin rpy="0.0 0.0 1.5707963267948966" xyz="0 0.0 0.0"/>
      <geometry>
        <mesh filename="package://sobit_edu_sim_description/meshes/arm/Assembly_4.stl" scale="1.0 1.0  1.0 "/>
      </geometry>
      <material name="black"/>
    </visual>
    <collision>
      <origin rpy="0.0 0.0 1.5707963267948966" xyz="0 0.0 0.0"/>
      <geometry>
        <mesh filename="package://sobit_edu_sim_description/meshes/arm/Assembly_4.stl" scale="1.0  1.0  1.0 "/>
      </geometry>
    </collision>
    <inertial>
      <origin rpy="0.0 0.0 0.0" xyz="0.0 0.0 0.0"/>
      <mass value="0.00008"/>
      <inertia ixx="1.0" ixy="0.0" ixz="0.0" iyy="1.0" iyz="0.0" izz="1.0"/>
    </inertial>
  </link>
  <!-- <joint name="${prefix}_shoulder_2_tilt_joint" type="revolute">
      <parent link="${prefix}_shoulder_pan_link" />
      <child link="${prefix}_shoulder_2_tilt_link" />
      <origin xyz="0.0 0.0 0.0405" rpy="0.0 0.0 ${M_PI}" />
      <axis xyz="0 -1 0" />
      <mimic joint="${prefix}_shoulder_1_tilt_joint" multiplier="1" offset="0" />
      <limit effort="30" lower="${-M_PI/2.0}" upper="${M_PI/2.0}" velocity="${M_PI/2.0}" />
    </joint>

    <link name="${prefix}_shoulder_2_tilt_link" /> -->
  <joint name="arm_elbow_1_tilt_joint" type="revolute">
    <parent link="arm_shoulder_1_tilt_link"/>
    <child link="arm_elbow_1_tilt_link"/>
    <origin rpy="1.5707963267948966 -1.5707963267948966 0.0" xyz="-0.148139 0.0 0.021810"/>
    <axis xyz="0 0 1"/>
    <limit effort="30" lower="-1.5707963267948966" upper="1.5707963267948966" velocity="1.5707963267948966"/>
  </joint>
  <link name="arm_elbow_1_tilt_link">
    <visual>
      <origin rpy="0.0 0.0 1.5707963267948966" xyz="0.0 0.0 0.0"/>
      <geometry>
        <mesh filename="package://sobit_edu_sim_description/meshes/arm/Assembly_5.stl" scale="1.0 1.0 1.0"/>
      </geometry>
      <material name="black"/>
    </visual>
    <collision>
      <origin rpy="0.0 0.0 1.5707963267948966" xyz="0.0 0.0 0.0"/>
      <geometry>
        <mesh filename="package://sobit_edu_sim_description/meshes/arm/Assembly_5.stl" scale="1.0 1.0 1.0"/>
      </geometry>
    </collision>
    <inertial>
      <origin rpy="0.0 0.0 1.5707963267948966" xyz="0.0 0.0 0.0"/>
      <mass value="0.00008"/>
      <inertia ixx="1.0" ixy="0.0" ixz="0.0" iyy="1.0" iyz="0.0" izz="1.0"/>
    </inertial>
  </link>
  <!-- <joint name="${prefix}_elbow_2_tilt_joint" type="revolute">
      <parent link="${prefix}_shoulder_1_tilt_link" />
      <child link="${prefix}_elbow_2_tilt_link" />
      <origin xyz="0.02538 0.0 0.148" rpy="0.0 0.0 ${M_PI}" />
      <axis xyz="0 1 0" />
      <mimic joint="${prefix}_elbow_1_tilt_joint" multiplier="1" offset="0" />
      <limit effort="30" lower="${-M_PI/2.0}" upper="${M_PI/2.0}" velocity="${M_PI/2.0}" />
    </joint>

    <link name="${prefix}_elbow_2_tilt_link" /> -->
  <joint name="arm_wrist_tilt_joint" type="revolute">
    <parent link="arm_elbow_1_tilt_link"/>
    <child link="arm_wrist_tilt_link"/>
    <origin rpy="1.5707963267948966 0.0 1.5707963267948966" xyz="0.149873  0.0 0.0"/>
    <axis xyz="0 -1 0"/>
    <limit effort="30" lower="-1.5707963267948966" upper="1.4155" velocity="1.5707963267948966"/>
  </joint>
  <link name="arm_wrist_tilt_link"/>
  <!-- <xacro:position_joint_transmission joint="${prefix}_base_link"    reduction="1" /> -->
  <transmission name="arm_shoulder_pan_joint_transmission">
    <type>transmission_interface/SimpleTransmission</type>
    <joint name="arm_shoulder_pan_joint">
      <hardwareInterface>hardware_interface/PositionJointInterface</hardwareInterface>
    </joint>
    <actuator name="arm_shoulder_pan_joint_actuator">
      <hardwareInterface>hardware_interface/PositionJointInterface</hardwareInterface>
      <mechanicalReduction>1</mechanicalReduction>
    </actuator>
  </transmission>
  <transmission name="arm_shoulder_1_tilt_joint_transmission">
    <type>transmission_interface/SimpleTransmission</type>
    <joint name="arm_shoulder_1_tilt_joint">
      <hardwareInterface>hardware_interface/PositionJointInterface</hardwareInterface>
    </joint>
    <actuator name="arm_shoulder_1_tilt_joint_actuator">
      <hardwareInterface>hardware_interface/PositionJointInterface</hardwareInterface>
      <mechanicalReduction>1</mechanicalReduction>
    </actuator>
  </transmission>
  <transmission name="arm_elbow_1_tilt_joint_transmission">
    <type>transmission_interface/SimpleTransmission</type>
    <joint name="arm_elbow_1_tilt_joint">
      <hardwareInterface>hardware_interface/PositionJointInterface</hardwareInterface>
    </joint>
    <actuator name="arm_elbow_1_tilt_joint_actuator">
      <hardwareInterface>hardware_interface/PositionJointInterface</hardwareInterface>
      <mechanicalReduction>1</mechanicalReduction>
    </actuator>
  </transmission>
  <transmission name="arm_wrist_tilt_joint_transmission">
    <type>transmission_interface/SimpleTransmission</type>
    <joint name="arm_wrist_tilt_joint">
      <hardwareInterface>hardware_interface/PositionJointInterface</hardwareInterface>
    </joint>
    <actuator name="arm_wrist_tilt_joint_actuator">
      <hardwareInterface>hardware_interface/PositionJointInterface</hardwareInterface>
      <mechanicalReduction>1</mechanicalReduction>
    </actuator>
  </transmission>
  <gazebo reference="arm_base_link">
    <selfCollide>false</selfCollide>
    <mu1>1.0</mu1>
    <mu2>1.0</mu2>
  </gazebo>
  <gazebo reference="arm_shoulder_pan_link">
    <selfCollide>false</selfCollide>
    <mu1>1.0</mu1>
    <mu2>1.0</mu2>
  </gazebo>
  <gazebo reference="arm_shoulder_1_tilt_link">
    <selfCollide>false</selfCollide>
    <mu1>1.0</mu1>
    <mu2>1.0</mu2>
  </gazebo>
  <gazebo reference="arm_elbow_1_tilt_link">
    <selfCollide>false</selfCollide>
    <mu1>1.0</mu1>
    <mu2>1.0</mu2>
  </gazebo>
  <gazebo reference="arm_wrist_tilt_link">
    <selfCollide>false</selfCollide>
    <mu1>1.0</mu1>
    <mu2>1.0</mu2>
  </gazebo>
  <gazebo>
    <plugin filename="libgazebo_ros_joint_state_publisher.so" name="joint_state_publisher">
      <jointName>arm_shoulder_pan_joint, arm_shoulder_1_tilt_joint, arm_elbow_1_tilt_joint, arm_wrist_tilt_joint</jointName>
      <updateRate>1000.0</updateRate>
    </plugin>
  </gazebo>
  <joint name="hand_base_l_joint" type="fixed">
    <parent link="arm_wrist_tilt_link"/>
    <child link="hand_base_l_link"/>
    <origin rpy="0.0 0.0 0.0" xyz="-0.02812 0.04061 0.05724"/>
  </joint>
  <joint name="hand_base_r_joint" type="fixed">
    <parent link="arm_wrist_tilt_link"/>
    <child link="hand_base_r_link"/>
    <origin rpy="0.0 0.0 0.0" xyz="-0.02812 -0.04061 0.05724"/>
  </joint>
  <link name="hand_base_l_link">
    <visual>
      <origin rpy="0.0 0.0 1.5707963267948966" xyz="0.02812 -0.04061 -0.05724"/>
      <geometry>
        <mesh filename="package://sobit_edu_sim_description/meshes/hand/hand_back.stl" scale="0.001 0.001 0.001"/>
      </geometry>
      <material name="black"/>
    </visual>
    <collision>
      <origin rpy="0.0 0.0 1.5707963267948966" xyz="0.02812 -0.04061 -0.05724"/>
      <geometry>
        <mesh filename="package://sobit_edu_sim_description/meshes/hand/hand_back.stl" scale="0.001 0.001 0.001"/>
      </geometry>
    </collision>
    <inertial>
      <origin rpy="0.0 0.0 0.0" xyz="0.0 0.0 0.0"/>
      <mass value="0.08"/>
      <inertia ixx="1.0" ixy="0.0" ixz="0.0" iyy="1.0" iyz="0.0" izz="1.0"/>
    </inertial>
  </link>
  <link name="hand_base_r_link">
    <visual>
      <origin rpy="0.0 0.0 1.5707963267948966" xyz="0.02812 0.04061 -0.05724"/>
      <geometry>
        <mesh filename="package://sobit_edu_sim_description/meshes/hand/hand_back.stl" scale="0.001 0.001 0.001"/>
      </geometry>
      <material name="black"/>
    </visual>
    <collision>
      <origin rpy="0.0 0.0 1.5707963267948966" xyz="0.02812 0.04061 -0.05724"/>
      <geometry>
        <mesh filename="package://sobit_edu_sim_description/meshes/hand/hand_back.stl" scale="0.001 0.001 0.001"/>
      </geometry>
    </collision>
    <inertial>
      <origin rpy="0.0 0.0 0.0" xyz="0.0 0.0 0.0"/>
      <mass value="0.08"/>
      <inertia ixx="1.0" ixy="0.0" ixz="0.0" iyy="1.0" iyz="0.0" izz="1.0"/>
    </inertial>
  </link>
  <joint name="hand_joint" type="revolute">
    <parent link="hand_base_l_link"/>
    <child link="hand_inner_l_link"/>
    <origin rpy="0.0 0.0 0.0" xyz="0 -0.02456 0.02054"/>
    <axis xyz="1 0 0"/>
    <!-- <mimic joint="${prefix_hand}_joint" multiplier="1.0" offset="0" /> -->
    <limit effort="1" lower="-1.5707963267948966" upper="0" velocity="1"/>
  </joint>
  <link name="hand_inner_l_link">
    <visual>
      <origin rpy="1.5707963267948966 0.0 1.5707963267948966" xyz="0.0 0.0 0.0"/>
      <geometry>
        <mesh filename="package://sobit_edu_sim_description/meshes/hand/hand_inner_l.stl" scale="0.001 0.001 0.001"/>
      </geometry>
      <material name="black"/>
    </visual>
    <collision>
      <origin rpy="1.5707963267948966 0.0 1.5707963267948966" xyz="0.0 0.0 0.0"/>
      <geometry>
        <mesh filename="package://sobit_edu_sim_description/meshes/hand/hand_inner_l.stl" scale="0.001 0.001 0.001"/>
      </geometry>
    </collision>
    <inertial>
      <origin rpy="0.0 0.0 0.0" xyz="0.0 0.0 0.0"/>
      <mass value="0.08"/>
      <inertia ixx="1.0" ixy="0.0" ixz="0.0" iyy="1.0" iyz="0.0" izz="1.0"/>
    </inertial>
  </link>
  <joint name="hand_inner_r_joint" type="revolute">
    <parent link="hand_base_r_link"/>
    <child link="hand_inner_r_link"/>
    <origin rpy="0.0 0.0 0.0" xyz="0 0.02456 0.02054"/>
    <axis xyz="-1 0 0"/>
    <mimic joint="hand_joint" multiplier="1.0" offset="0"/>
    <limit effort="1" lower="-1.5707963267948966" upper="0" velocity="1"/>
  </joint>
  <link name="hand_inner_r_link">
    <visual>
      <origin rpy="1.5707963267948966 0.0 1.5707963267948966" xyz="0.0 0.0 0.0"/>
      <geometry>
        <mesh filename="package://sobit_edu_sim_description/meshes/hand/hand_inner_r.stl" scale="0.001 0.001 0.001"/>
      </geometry>
      <material name="black"/>
    </visual>
    <collision>
      <origin rpy="1.5707963267948966 0.0 1.5707963267948966" xyz="0.0 0.0 0.0"/>
      <geometry>
        <mesh filename="package://sobit_edu_sim_description/meshes/hand/hand_inner_r.stl" scale="0.001 0.001 0.001"/>
      </geometry>
    </collision>
    <inertial>
      <origin rpy="0.0 0.0 0.0" xyz="0.0 0.0 0.0"/>
      <mass value="0.08"/>
      <inertia ixx="1.0" ixy="0.0" ixz="0.0" iyy="1.0" iyz="0.0" izz="1.0"/>
    </inertial>
  </link>
  <joint name="hand_finger_l_joint" type="continuous">
    <parent link="hand_inner_l_link"/>
    <child link="hand_finger_l_link"/>
    <origin rpy="0.0 0.0 0.0" xyz="0.019 0 0.08"/>
    <axis xyz="1 0 0"/>
    <!-- <mimic joint="${prefix_hand}_joint" multiplier="1.0" offset="0" /> -->
    <!-- <limit lower="${-M_PI/2.0}" upper="0" effort="1" velocity="1" /> -->
  </joint>
  <link name="hand_finger_l_link">
    <visual>
      <origin rpy="1.5707963267948966 0.0 1.5707963267948966" xyz="0.0 0.025 -0.03"/>
      <geometry>
        <mesh filename="package://sobit_edu_sim_description/meshes/hand/hand_finger_l.stl" scale="0.001 0.001 0.001"/>
      </geometry>
      <material name="black"/>
    </visual>
    <collision>
      <origin rpy="1.5707963267948966 0.0 1.5707963267948966" xyz="0.0 0.025 -0.03"/>
      <geometry>
        <mesh filename="package://sobit_edu_sim_description/meshes/hand/hand_finger_l.stl" scale="0.001 0.001 0.001"/>
      </geometry>
    </collision>
    <inertial>
      <origin rpy="0.0 0.0 0.0" xyz="0.0 0.025 -0.03"/>
      <mass value="0.08"/>
      <inertia ixx="1.0" ixy="0.0" ixz="0.0" iyy="1.0" iyz="0.0" izz="1.0"/>
    </inertial>
  </link>
  <joint name="hand_finger_r_joint" type="continuous">
    <parent link="hand_inner_r_link"/>
    <child link="hand_finger_r_link"/>
    <origin rpy="0.0 0.0 0.0" xyz="0.019 0 0.08"/>
    <axis xyz="-1 0 0"/>
    <mimic joint="hand_finger_l_joint" multiplier="1.0" offset="0"/>
    <!-- <limit lower="${-M_PI/2.0}" upper="0" effort="1" velocity="1" /> -->
  </joint>
  <link name="hand_finger_r_link">
    <visual>
      <origin rpy="1.5707963267948966 0.0 1.5707963267948966" xyz="0.0 -0.025 -0.03"/>
      <geometry>
        <mesh filename="package://sobit_edu_sim_description/meshes/hand/hand_finger_r.stl" scale="0.001 0.001 0.001"/>
      </geometry>
      <material name="black"/>
    </visual>
    <collision>
      <origin rpy="1.5707963267948966 0.0 1.5707963267948966" xyz="0.0 -0.025 -0.03"/>
      <geometry>
        <mesh filename="package://sobit_edu_sim_description/meshes/hand/hand_finger_r.stl" scale="0.001 0.001 0.001"/>
      </geometry>
    </collision>
    <inertial>
      <origin rpy="0.0 0.0 0.0" xyz="0.0 -0.025 -0.03"/>
      <mass value="0.08"/>
      <inertia ixx="1.0" ixy="0.0" ixz="0.0" iyy="1.0" iyz="0.0" izz="1.0"/>
    </inertial>
  </link>
  <joint name="hand_outer_l_joint" type="continuous">
    <parent link="hand_finger_l_link"/>
    <child link="hand_outer_l_link"/>
    <origin rpy="0.0 0.0 0.0" xyz="-0.015 0.025 -0.03"/>
    <axis xyz="1 0 0"/>
    <!-- <mimic joint="${prefix_hand}_joint" multiplier="1.0" offset="0" /> -->
    <!-- <limit lower="${-M_PI/2.0}" upper="0" effort="1" velocity="1" /> -->
  </joint>
  <link name="hand_outer_l_link">
    <visual>
      <origin rpy="1.5707963267948966 0.0 1.5707963267948966" xyz="-0.004 0.0 -0.07"/>
      <geometry>
        <mesh filename="package://sobit_edu_sim_description/meshes/hand/hand_outer_l.stl" scale="0.001 0.001 0.001"/>
      </geometry>
      <material name="black"/>
    </visual>
    <collision>
      <origin rpy="1.5707963267948966 0.0 1.5707963267948966" xyz="-0.004 0.0 -0.07"/>
      <geometry>
        <mesh filename="package://sobit_edu_sim_description/meshes/hand/hand_outer_l.stl" scale="0.001 0.001 0.001"/>
      </geometry>
    </collision>
    <inertial>
      <origin rpy="0.0 0.0 0.0" xyz="-0.004 0.0 -0.07"/>
      <mass value="0.08"/>
      <inertia ixx="1.0" ixy="0.0" ixz="0.0" iyy="1.0" iyz="0.0" izz="1.0"/>
    </inertial>
  </link>
  <joint name="hand_outer_r_joint" type="continuous">
    <parent link="hand_finger_r_link"/>
    <child link="hand_outer_r_link"/>
    <origin rpy="0.0 0.0 0.0" xyz="-0.015 -0.025 -0.03"/>
    <axis xyz="-1 0 0"/>
    <mimic joint="hand_outer_l_joint" multiplier="1.0" offset="0"/>
    <!-- <limit lower="${-M_PI/2.0}" upper="0" effort="1" velocity="1" /> -->
  </joint>
  <link name="hand_outer_r_link">
    <visual>
      <origin rpy="1.5707963267948966 0.0 1.5707963267948966" xyz="-0.004 0.0 -0.07"/>
      <geometry>
        <mesh filename="package://sobit_edu_sim_description/meshes/hand/hand_outer_r.stl" scale="0.001 0.001 0.001"/>
      </geometry>
      <material name="black"/>
    </visual>
    <collision>
      <origin rpy="1.5707963267948966 0.0 1.5707963267948966" xyz="-0.004 0.0 -0.07"/>
      <geometry>
        <mesh filename="package://sobit_edu_sim_description/meshes/hand/hand_outer_r.stl" scale="0.001 0.001 0.001"/>
      </geometry>
    </collision>
    <inertial>
      <origin rpy="0.0 0.0 0.0" xyz="0.0 0.0 0.0"/>
      <mass value="0.08"/>
      <inertia ixx="1.0" ixy="0.0" ixz="0.0" iyy="1.0" iyz="0.0" izz="1.0"/>
    </inertial>
  </link>
  <transmission name="hand_joint_transmission">
    <type>transmission_interface/SimpleTransmission</type>
    <joint name="hand_joint">
      <hardwareInterface>hardware_interface/PositionJointInterface</hardwareInterface>
    </joint>
    <actuator name="hand_joint_actuator">
      <hardwareInterface>hardware_interface/PositionJointInterface</hardwareInterface>
      <mechanicalReduction>1</mechanicalReduction>
    </actuator>
  </transmission>
  <transmission name="hand_inner_r_joint_transmission">
    <type>transmission_interface/SimpleTransmission</type>
    <joint name="hand_inner_r_joint">
      <hardwareInterface>hardware_interface/PositionJointInterface</hardwareInterface>
    </joint>
    <actuator name="hand_inner_r_joint_actuator">
      <hardwareInterface>hardware_interface/PositionJointInterface</hardwareInterface>
      <mechanicalReduction>1</mechanicalReduction>
    </actuator>
  </transmission>
  <transmission name="hand_outer_l_joint_transmission">
    <type>transmission_interface/SimpleTransmission</type>
    <joint name="hand_outer_l_joint">
      <hardwareInterface>hardware_interface/PositionJointInterface</hardwareInterface>
    </joint>
    <actuator name="hand_outer_l_joint_actuator">
      <hardwareInterface>hardware_interface/PositionJointInterface</hardwareInterface>
      <mechanicalReduction>1</mechanicalReduction>
    </actuator>
  </transmission>
  <transmission name="hand_outer_r_joint_transmission">
    <type>transmission_interface/SimpleTransmission</type>
    <joint name="hand_outer_r_joint">
      <hardwareInterface>hardware_interface/PositionJointInterface</hardwareInterface>
    </joint>
    <actuator name="hand_outer_r_joint_actuator">
      <hardwareInterface>hardware_interface/PositionJointInterface</hardwareInterface>
      <mechanicalReduction>1</mechanicalReduction>
    </actuator>
  </transmission>
  <transmission name="hand_finger_l_joint_transmission">
    <type>transmission_interface/SimpleTransmission</type>
    <joint name="hand_finger_l_joint">
      <hardwareInterface>hardware_interface/PositionJointInterface</hardwareInterface>
    </joint>
    <actuator name="hand_finger_l_joint_actuator">
      <hardwareInterface>hardware_interface/PositionJointInterface</hardwareInterface>
      <mechanicalReduction>1</mechanicalReduction>
    </actuator>
  </transmission>
  <transmission name="hand_finger_r_joint_transmission">
    <type>transmission_interface/SimpleTransmission</type>
    <joint name="hand_finger_r_joint">
      <hardwareInterface>hardware_interface/PositionJointInterface</hardwareInterface>
    </joint>
    <actuator name="hand_finger_r_joint_actuator">
      <hardwareInterface>hardware_interface/PositionJointInterface</hardwareInterface>
      <mechanicalReduction>1</mechanicalReduction>
    </actuator>
  </transmission>
  <gazebo reference="hand_base_link">
    <selfCollide>false</selfCollide>
    <mu1>1.0</mu1>
    <mu2>1.0</mu2>
  </gazebo>
  <gazebo reference="hand_inner_l_link">
    <selfCollide>false</selfCollide>
    <mu1>1.0</mu1>
    <mu2>1.0</mu2>
  </gazebo>
  <gazebo reference="hand_inner_r_link">
    <selfCollide>false</selfCollide>
    <mu1>1.0</mu1>
    <mu2>1.0</mu2>
  </gazebo>
  <gazebo reference="hand_outer_l_link">
    <selfCollide>false</selfCollide>
    <mu1>1.0</mu1>
    <mu2>1.0</mu2>
  </gazebo>
  <gazebo reference="hand_outer_r_link">
    <selfCollide>false</selfCollide>
    <mu1>1.0</mu1>
    <mu2>1.0</mu2>
  </gazebo>
  <gazebo reference="hand_finger_l_link">
    <selfCollide>false</selfCollide>
    <mu1>1.0</mu1>
    <mu2>1.0</mu2>
  </gazebo>
  <gazebo reference="hand_finger_l_link">
    <selfCollide>false</selfCollide>
    <mu1>1.0</mu1>
    <mu2>1.0</mu2>
  </gazebo>
  <gazebo>
    <plugin filename="libgazebo_ros_joint_state_publisher.so" name="joint_state_publisher">
      <jointName>hand_joint, hand_inner_r_joint, hand_finger_l_joint, hand_finger_r_joint, hand_outer_l_joint, hand_outer_r_joint</jointName>
      <updateRate>1000.0</updateRate>
    </plugin>
  </gazebo>
  <joint name="back_base_joint" type="fixed">
    <parent link="plate_top_link"/>
    <child link="back_base_link"/>
    <origin rpy="0.0 0.0 0.0" xyz="-0.070405 0.0 0.00325"/>
  </joint>
  <link name="back_base_link">
    <visual>
      <origin rpy="0.0 0.0 1.5707963267948966" xyz="0.0 0.0 0.0"/>
      <geometry>
        <mesh filename="package://sobit_edu_sim_description/meshes/back/back_base.stl" scale="0.001 0.001 0.001"/>
      </geometry>
      <material name="grey"/>
    </visual>
    <collision>
      <origin rpy="0.0 0.0 1.5707963267948966" xyz="0.0 0.0 0.0"/>
      <geometry>
        <mesh filename="package://sobit_edu_sim_description/meshes/back/back_base.stl" scale="0.001 0.001 0.001"/>
      </geometry>
    </collision>
    <inertial>
      <origin rpy="0.0 0.0 0.0" xyz="0.0 0.0 0.0"/>
      <mass value="0.00004"/>
      <inertia ixx="1.0" ixy="0.0" ixz="0.0" iyy="1.0" iyz="0.0" izz="1.0"/>
    </inertial>
  </link>
  <joint name="head_camera_base_joint" type="fixed">
    <parent link="back_base_link"/>
    <child link="head_camera_base_link"/>
    <origin rpy="0.0 0.0 0.0" xyz="0.150 0.0 0.370"/>
  </joint>
  <link name="head_camera_base_link">
    <visual>
      <origin rpy="1.5707963267948966 0.0 1.5707963267948966" xyz="0.0 0.0 0.0"/>
      <geometry>
        <mesh filename="package://sobit_edu_sim_description/meshes/head/head_camera_base.stl" scale="0.001 0.001 0.001"/>
      </geometry>
      <material name="black"/>
    </visual>
    <collision>
      <origin rpy="1.5707963267948966 0.0 1.5707963267948966" xyz="0.0 0.0 0.0"/>
      <geometry>
        <mesh filename="package://sobit_edu_sim_description/meshes/head/head_camera_base.stl" scale="0.001 0.001 0.001"/>
      </geometry>
    </collision>
    <inertial>
      <origin rpy="1.5707963267948966 0.0 1.5707963267948966" xyz="0.0 0.0 0.0"/>
      <mass value="0.08"/>
      <inertia ixx="1.0" ixy="0.0" ixz="0.0" iyy="1.0" iyz="0.0" izz="1.0"/>
    </inertial>
  </link>
  <joint name="head_camera_pan_joint" type="revolute">
    <parent link="head_camera_base_link"/>
    <child link="head_camera_pan_link"/>
    <origin rpy="0.0 0.0 0.0" xyz="0.04125 0.0 0.0255"/>
    <axis xyz="0 0 1"/>
    <limit effort="30" lower="-1.5707963267948966" upper="1.5707963267948966" velocity="1.5707963267948966"/>
  </joint>
  <link name="head_camera_pan_link">
    <visual>
      <origin rpy="0.0 0.0 -1.5707963267948966" xyz="0.0 0.0 0.0"/>
      <geometry>
        <mesh filename="package://sobit_edu_sim_description/meshes/head/head_camera_pan.stl" scale="0.001 0.001 0.001"/>
      </geometry>
      <material name="black"/>
    </visual>
    <collision>
      <origin rpy="0.0 0.0 -1.5707963267948966" xyz="0.0 0.0 0.0"/>
      <geometry>
        <mesh filename="package://sobit_edu_sim_description/meshes/head/head_camera_pan.stl" scale="0.001 0.001 0.001"/>
      </geometry>
    </collision>
    <inertial>
      <origin rpy="0.0 0.0 -1.5707963267948966" xyz="0.0 0.0 0.0"/>
      <mass value="0.08"/>
      <inertia ixx="1.0" ixy="0.0" ixz="0.0" iyy="1.0" iyz="0.0" izz="1.0"/>
    </inertial>
  </link>
  <joint name="head_camera_tilt_joint" type="revolute">
    <parent link="head_camera_pan_link"/>
    <child link="head_camera_tilt_link"/>
    <origin rpy="0.0 0.0 0.0" xyz="0.0 0.0 0.0435"/>
    <axis xyz="0 -1 0"/>
    <limit effort="30" lower="-1.5707963267948966" upper="1.5707963267948966" velocity="1.5707963267948966"/>
  </joint>
  <link name="head_camera_tilt_link">
    <visual>
      <origin rpy="0.0 0.0 1.5707963267948966" xyz="0.0 0.0 0.0"/>
      <geometry>
        <mesh filename="package://sobit_edu_sim_description/meshes/head/head_camera_tilt.stl" scale="0.001 0.001 0.001"/>
      </geometry>
      <material name="black"/>
    </visual>
    <collision>
      <origin rpy="0.0 0.0 1.5707963267948966" xyz="0.0 0.0 0.0"/>
      <geometry>
        <mesh filename="package://sobit_edu_sim_description/meshes/head/head_camera_tilt.stl" scale="0.001 0.001 0.001"/>
      </geometry>
    </collision>
    <inertial>
      <origin rpy="0.0 0.0 1.5707963267948966" xyz="0.0 0.0 0.0"/>
      <mass value="0.08"/>
      <inertia ixx="1.0" ixy="0.0" ixz="0.0" iyy="1.0" iyz="0.0" izz="1.0"/>
    </inertial>
  </link>
  <transmission name="head_camera_pan_joint_transmission">
    <type>transmission_interface/SimpleTransmission</type>
    <joint name="head_camera_pan_joint">
      <hardwareInterface>hardware_interface/PositionJointInterface</hardwareInterface>
    </joint>
    <actuator name="head_camera_pan_joint_actuator">
      <hardwareInterface>hardware_interface/PositionJointInterface</hardwareInterface>
      <mechanicalReduction>1</mechanicalReduction>
    </actuator>
  </transmission>
  <transmission name="head_camera_tilt_joint_transmission">
    <type>transmission_interface/SimpleTransmission</type>
    <joint name="head_camera_tilt_joint">
      <hardwareInterface>hardware_interface/PositionJointInterface</hardwareInterface>
    </joint>
    <actuator name="head_camera_tilt_joint_actuator">
      <hardwareInterface>hardware_interface/PositionJointInterface</hardwareInterface>
      <mechanicalReduction>1</mechanicalReduction>
    </actuator>
  </transmission>
  <gazebo reference="head_camera_base_link">
    <selfCollide>false</selfCollide>
    <mu1>1.0</mu1>
    <mu2>1.0</mu2>
  </gazebo>
  <gazebo reference="head_camera_pan_link">
    <selfCollide>false</selfCollide>
    <mu1>1.0</mu1>
    <mu2>1.0</mu2>
  </gazebo>
  <gazebo reference="head_camera_tilt_link">
    <selfCollide>false</selfCollide>
    <mu1>1.0</mu1>
    <mu2>1.0</mu2>
  </gazebo>
  <gazebo>
    <plugin filename="libgazebo_ros_joint_state_publisher.so" name="joint_state_publisher">
      <jointName>head_camera_pan_joint, head_camera_tilt_joint</jointName>
      <updateRate>1000.0</updateRate>
    </plugin>
  </gazebo>
  <joint name="head_camera_joint" type="fixed">
    <parent link="head_camera_tilt_link"/>
    <child link="head_camera_link"/>
    <origin rpy="0.0 0.0 0.0" xyz="-0.0065 0.0 0.0395"/>
  </joint>
  <link name="head_camera_link"/>
  <joint name="head_camera_plug_base_joint" type="fixed">
    <origin rpy="0 0 0" xyz="0.0 0 0.0"/>
    <parent link="head_camera_link"/>
    <child link="head_camera_plug_base_link"/>
  </joint>
  <link name="head_camera_plug_base_link">
    <visual>
      <origin rpy="0.0 0.0 0.0" xyz="0.0 0.0 0.0"/>
      <geometry>
        <mesh filename="package://azure_kinect_ros_driver/meshes/akdk_camera.dae"/>
      </geometry>
    </visual>
    <collision>
      <origin rpy="0.0 0.0 0.0" xyz="-0.013700000000000004 0.0 0.0111"/>
      <!-- <origin xyz="0.0 0.0 0.0" rpy="0.0 0.0 0.0" /> -->
      <geometry>
        <box size="0.0994 0.09637 0.0222"/>
        <!-- <mesh filename="package://azure_kinect_ros_driver/meshes/akdk_camera.dae" /> -->
      </geometry>
    </collision>
    <inertial>
      <origin rpy="0.0 0.0 0.0" xyz="-0.013700000000000004 0.0 0.0111"/>
      <mass value="0.000440"/>
      <inertia ixx="0.0003803506666666667" ixy="0.0" ixz="0.0" iyy="0.00035860061966666665" iyz="0.0" izz="0.0007028096863333334"/>
      <!-- <inertia ixx="1.0" ixy="0.0" ixz="0.0"
                iyy="1.0" iyz="0.0"
                izz="1.0" /> -->
    </inertial>
  </link>
  <joint name="head_camera_visor_base_joint" type="fixed">
    <parent link="head_camera_plug_base_link"/>
    <child link="head_camera_visor_base_link"/>
    <origin rpy="0.0 0.0 0.0" xyz="0.062 0.0 0.005"/>
  </joint>
  <link name="head_camera_visor_base_link">
    <collision>
      <origin rpy="0.0 0.0 0.0" xyz="-0.013 0.0 0.0"/>
      <geometry>
        <box size="0.026 0.103 0.039"/>
      </geometry>
    </collision>
  </link>
  <!-- <joint name="${tf_prefix}depth_optical_joint" type="fixed">
      <parent link="${tf_prefix}visor_base_link" />
      <child link="${tf_prefix}depth_optical_link" />
      <origin xyz="0.0 0.0 0.0018" rpy="0.0 0.0 0.0" />
    </joint>

    <link name="${tf_prefix}depth_optical_link" /> -->
  <!-- <joint name="${tf_prefix}rgb_optical_joint" type="fixed">
      <parent link="${tf_prefix}visor_base_link" />
      <child link="${tf_prefix}rgb_optical_link" />
      <origin xyz="0.0 -0.0320 0.0" rpy="0.0 0.0 0.0" />
    </joint>

    <link name="${tf_prefix}rgb_optical_link" /> -->
  <joint name="mic_base_joint" type="fixed">
    <parent link="back_base_link"/>
    <child link="mic_base_link"/>
    <origin rpy="0.0 0.0 0.0" xyz="0.190 0.0 0.610"/>
  </joint>
  <link name="mic_base_link">
    <visual>
      <origin rpy="1.5707963267948966 0 1.5707963267948966" xyz="0.0 0.0 0.0"/>
      <geometry>
        <mesh filename="package://sobit_edu_sim_description/meshes/sensor/mic_base.stl" scale="0.001 0.001 0.001"/>
      </geometry>
      <material name="black"/>
    </visual>
    <collision>
      <origin rpy="1.5707963267948966 0 1.5707963267948966" xyz="0.0 0.0 0.0"/>
      <geometry>
        <mesh filename="package://sobit_edu_sim_description/meshes/sensor/mic_base.stl" scale="0.001 0.001 0.001"/>
      </geometry>
      <material name="black"/>
    </collision>
    <inertial>
      <origin rpy="0 0 0" xyz="0.0 0.0 0.0"/>
      <mass value="1"/>
      <inertia ixx="1.0" ixy="0.0" ixz="0.0" iyy="1.0" iyz="0.0" izz="1.0"/>
    </inertial>
  </link>
  <joint name="mic_joint" type="fixed">
    <parent link="mic_base_link"/>
    <child link="mic_link"/>
    <origin rpy="0.0 0.0 0.0" xyz="-0.017007 0.0 0.020"/>
  </joint>
  <link name="mic_link">
    <visual>
      <origin rpy="3.141592653589793 0.0 1.5707963267948966" xyz="0.0 0.0 0.0"/>
      <geometry>
        <mesh filename="package://sobit_edu_sim_description/meshes/sensor/mic.stl" scale="0.001 0.001 0.001"/>
      </geometry>
      <material name="black"/>
    </visual>
    <collision>
      <origin rpy="3.141592653589793 0.0 1.5707963267948966" xyz="0.0 0.0 0.0"/>
      <geometry>
        <mesh filename="package://sobit_edu_sim_description/meshes/sensor/mic.stl" scale="0.001 0.001 0.001"/>
      </geometry>
      <material name="black"/>
    </collision>
    <inertial>
      <origin rpy="0.0 0.0 0.0" xyz="0.0 0.0 0.0"/>
      <mass value="1"/>
      <inertia ixx="1.0" ixy="0.0" ixz="0.0" iyy="1.0" iyz="0.0" izz="1.0"/>
    </inertial>
  </link>
  <!-- Matrix Base -->
  <joint name="matrix_base_joint" type="fixed">
    <parent link="back_base_link"/>
    <child link="matrix_base_link"/>
    <origin rpy="0.0 0.0 0.0" xyz="0.0 0.0 0.620"/>
  </joint>
  <link name="matrix_base_link">
    <visual>
      <origin rpy="0.0 0.0 0.0" xyz="0.0 0.0 0.0"/>
      <geometry>
        <mesh filename="package://sobit_edu_sim_description/meshes/sensor/matrix_base.stl" scale="0.001 0.001 0.001"/>
      </geometry>
      <material name="black"/>
    </visual>
    <collision>
      <origin rpy="0.0 0.0 0.0" xyz="0.0 0.0 0.0"/>
      <geometry>
        <mesh filename="package://sobit_edu_sim_description/meshes/sensor/matrix_base.stl" scale="0.001 0.001 0.001"/>
      </geometry>
    </collision>
    <inertial>
      <origin rpy="0.0 0.0 0.0" xyz="0.0 0.0 0.0"/>
      <mass value="1"/>
      <inertia ixx="1.0" ixy="0.0" ixz="0.0" iyy="1.0" iyz="0.0" izz="1.0"/>
    </inertial>
  </link>
  <!-- MATRIX Creator -->
  <joint name="matrix_board_joint" type="fixed">
    <parent link="matrix_base_link"/>
    <child link="matrix_board_link"/>
    <origin rpy="0.0 0.0 0.0" xyz="0.0 0.0 0.0295"/>
  </joint>
  <link name="matrix_board_link">
    <visual>
      <origin rpy="0.0 0.0 3.141592653589793" xyz="0.0 0.0 0.0"/>
      <geometry>
        <mesh filename="package://sobit_edu_sim_description/meshes/sensor/matrix.stl" scale="0.001 0.001 0.001"/>
      </geometry>
      <material name="blue"/>
    </visual>
    <collision>
      <origin rpy="0.0 0.0 0.0" xyz="0.0 0.0 0.0"/>
      <geometry>
        <mesh filename="package://sobit_edu_sim_description/meshes/sensor/matrix.stl" scale="0.001 0.001 0.001"/>
      </geometry>
    </collision>
    <inertial>
      <origin rpy="0.0 0.0 0.0" xyz="0.0 0.0 0.0"/>
      <mass value="1"/>
      <inertia ixx="1.0" ixy="0.0" ixz="0.0" iyy="1.0" iyz="0.0" izz="1.0"/>
    </inertial>
  </link>
  <joint name="matrix_sensor_1_joint" type="fixed">
    <origin rpy="0.0 0.0 0.0" xyz="-0.048503675 0.020090879 0.0"/>
    <parent link="matrix_board_link"/>
    <child link="matrix_sensor_1_link"/>
  </joint>
  <link name="matrix_sensor_1_link"/>
  <joint name="matrix_sensor_2_joint" type="fixed">
    <origin rpy="0.0 0.0 0.0" xyz="-0.048503675 -0.020090879 0.0"/>
    <parent link="matrix_board_link"/>
    <child link="matrix_sensor_2_link"/>
  </joint>
  <link name="matrix_sensor_2_link"/>
  <joint name="matrix_sensor_3_joint" type="fixed">
    <origin rpy="0.0 0.0 0.0" xyz="-0.020090879 -0.048503675 0.0"/>
    <parent link="matrix_board_link"/>
    <child link="matrix_sensor_3_link"/>
  </joint>
  <link name="matrix_sensor_3_link"/>
  <joint name="matrix_sensor_4_joint" type="fixed">
    <origin rpy="0.0 0.0 0.0" xyz="0.020090879 -0.048503675 0.0"/>
    <parent link="matrix_board_link"/>
    <child link="matrix_sensor_4_link"/>
  </joint>
  <link name="matrix_sensor_4_link"/>
  <joint name="matrix_sensor_5_joint" type="fixed">
    <origin rpy="0.0 0.0 0.0" xyz="0.048503675 -0.020090879 0.0"/>
    <parent link="matrix_board_link"/>
    <child link="matrix_sensor_5_link"/>
  </joint>
  <link name="matrix_sensor_5_link"/>
  <joint name="matrix_sensor_6_joint" type="fixed">
    <origin rpy="0.0 0.0 0.0" xyz="0.048503675 0.020090879 0.0"/>
    <parent link="matrix_board_link"/>
    <child link="matrix_sensor_6_link"/>
  </joint>
  <link name="matrix_sensor_6_link"/>
  <joint name="matrix_sensor_7_joint" type="fixed">
    <origin rpy="0.0 0.0 0.0" xyz="0.020090879 0.048503675 0.0"/>
    <parent link="matrix_board_link"/>
    <child link="matrix_sensor_7_link"/>
  </joint>
  <link name="matrix_sensor_7_link"/>
  <joint name="matrix_sensor_8_joint" type="fixed">
    <origin rpy="0.0 0.0 0.0" xyz="-0.020090879 0.048503675 0.0"/>
    <parent link="matrix_board_link"/>
    <child link="matrix_sensor_8_link"/>
  </joint>
  <link name="matrix_sensor_8_link"/>
  <joint name="lidar_base_joint" type="fixed">
    <origin rpy="0.0 0.0 0.0" xyz="0.08525 0.0 0.008"/>
    <parent link="plate_bottom_link"/>
    <child link="lidar_base_link"/>
  </joint>
  <link name="lidar_base_link">
    <visual>
      <origin rpy="0.0 0.0 3.141592653589793" xyz="0.0 0.0 0.0"/>
      <geometry>
        <mesh filename="package://sobit_edu_sim_description/meshes/sensor/lidar_base.stl" scale="0.001 0.001 0.001"/>
      </geometry>
      <material name="black"/>
    </visual>
    <collision>
      <origin rpy="0.0 0.0 3.141592653589793" xyz="0.0 0.0 0.0"/>
      <geometry>
        <mesh filename="package://sobit_edu_sim_description/meshes/sensor/lidar_base.stl" scale="0.001 0.001 0.001"/>
      </geometry>
    </collision>
    <inertial>
      <origin rpy="0.0 0.0 0.0" xyz="0.0 0 0.0"/>
      <mass value="0.000001"/>
      <inertia ixx="0.0001" ixy="0.0" ixz="0.0" iyy="0.0001" iyz="0.0" izz="0.0001"/>
    </inertial>
  </link>
  <joint name="lidar_laser_mount_joint" type="fixed">
    <origin rpy="0.0 0.0 0.0" xyz="0.1105 0.0 0.0"/>
    <parent link="lidar_base_link"/>
    <child link="lidar_laser_mount"/>
  </joint>
  <link name="lidar_laser_mount">
    <visual>
      <origin rpy="0 0 0" xyz="0 0 0"/>
      <geometry>
        <!-- Origin of this mesh is the base of the bracket. -->
        <mesh filename="package://urg_node/meshes/hokuyo_ust.stl"/>
      </geometry>
      <material name="dark_grey"/>
    </visual>
  </link>
  <joint name="lidar_laser_joint" type="fixed">
    <!-- This offset is from the base of the bracket to the LIDAR's focal point. -->
    <origin rpy="0 0 0" xyz="0 0 0.0474"/>
    <parent link="lidar_laser_mount"/>
    <child link="lidar_laser"/>
  </joint>
  <link name="lidar_laser">
    <inertial>
      <mass value="1.3"/>
      <origin xyz="0 0 0"/>
      <inertia ixx="0.0036300318813199993" ixy="0.0" ixz="0.0" iyy="0.00369730685441" iyz="0.0" izz="0.0023214740714099995"/>
    </inertial>
  </link>
  <gazebo reference="lidar_laser">
    <turnGravityOff>true</turnGravityOff>
    <sensor name="lidar_laser" type="ray">
      <pose>0 0 0 0 0 0</pose>
      <visualize>false</visualize>
      <update_rate>50.0</update_rate>
      <ray>
        <scan>
          <horizontal>
            <samples>720</samples>
            <resolution>1</resolution>
            <min_angle>-2.35619</min_angle>
            <max_angle>2.35619</max_angle>
          </horizontal>
        </scan>
        <range>
          <min>0.1</min>
          <max>60.0</max>
          <resolution>0.01</resolution>
        </range>
        <noise>
          <type>gaussian</type>
          <mean>0.0</mean>
          <stddev>0.001</stddev>
        </noise>
      </ray>
      <plugin filename="libgazebo_ros_laser.so" name="gazebo_ros_laser">
        <topicName>scan</topicName>
        <frameName>lidar_laser</frameName>
        <!-- <robotNamespace>${robot_namespace}</robotNamespace> -->
      </plugin>
    </sensor>
  </gazebo>
  <!-- <gazebo reference="${prefix}_laser_mount">
      <material>Gazebo/DarkGrey</material>
    </gazebo> -->
  <gazebo>
    <plugin filename="libgazebo_ros_control.so" name="gazebo_ros_control">
      <updateRate>100.0</updateRate>
    </plugin>
  </gazebo>
</robot>

